Workbook

Sheet 1. Thong tin chung
A1: BÁO CÁO TÀI CHÍNH NĂM 2026 (CHUỖI BÁN LẺ VIETMART)
A2: CÔNG TY CỔ PHẦN BÁCH HÓA VIỆT (VIETMART DISTRIBUTION JSC)
A3: Hệ thống 28 Siêu thị tiện ích & Trung tâm Phân phối FMCG Miền Nam - Áp dụng Thông tư 200/2014/TT-BTC
A5: I. THÔNG TIN PHÁP LÝ & HỆ THỐNG PHÂN PHỐI
A6: • | B6: Tên đầy đủ | D6: CÔNG TY CỔ PHẦN BÁCH HÓA VIỆT
A7: • | B7: Tên giao dịch quốc tế | D7: VIETMART DISTRIBUTION JOINT STOCK COMPANY
A8: • | B8: Mã số thuế / Giấy phép ĐKKD | D8: 0312345678 (Đăng ký thay đổi lần thứ 6 ngày 12/04/2025)
A9: • | B9: Vốn điều lệ thực góp | D9: 10.000.000.000 VNĐ (Mười tỷ đồng - 1.000.000 cổ phần)
A10: • | B10: Trụ sở điều hành chính | D10: Số 128 Đường Nguyễn Thị Minh Khai, Phường 6, Quận 3, TP. Hồ Chí Minh
A11: • | B11: Quy mô hạ tầng kinh doanh | D11: Chuỗi 28 siêu thị VietMart Mart, 02 Tổng kho logistics tại Bình Dương & Long An
A12: • | B12: Ngành nghề kinh doanh chính | D12: Bán buôn, bán lẻ lương thực, thực phẩm, đồ uống, hóa mỹ phẩm và thiết bị gia dụng
A13: • | B13: Người đại diện pháp luật | D13: Bà NGUYỄN HOÀNG MAI - Tổng Giám đốc
A14: • | B14: Kế toán trưởng | D14: Ông PHẠM MINH ĐỨC
A15: • | B15: Tổ chức kiểm toán độc lập | D15: Công ty TNHH Kiểm toán & Thẩm định giá PwC Việt Nam
A16: • | B16: Đặc thù mô hình kinh doanh | D16: Bán lẻ thu tiền ngay, vòng quay tồn kho nhanh, đòn bẩy chiếm dụng vốn nhà cung cấp cao
A18: II. TỔNG HỢP CÁC CHỈ SỐ TÀI CHÍNH CỐT LÕI (NGÀNH BÁN LẺ & CHUỖI PHÂN PHỐI)
A19: STT | B19: Chỉ tiêu tài chính | C19: ĐVT | D19: Năm 2026 | E19: Năm 2025 | F19: Chênh lệch (+/-) | G19: Tăng trưởng
A20: 1 | B20: Doanh thu thuần bán hàng & CCDV | C20: VNĐ | D20: 86500000000 | E20: 72800000000 | F20: =D20-E20 | G20: =F20/E20
A21: 2 | B21: Lợi nhuận gộp | C21: VNĐ | D21: 17300000000 | E21: 14268800000 | F21: =D21-E21 | G21: =F21/E21
A22: 3 | B22: Lợi nhuận kế toán trước thuế (LNTT) | C22: VNĐ | D22: 3750000000 | E22: 2125000000 | F22: =D22-E22 | G22: =F22/E22
A23: 4 | B23: Lợi nhuận sau thuế TNDN (LNST) | C23: VNĐ | D23: 3000000000 | E23: 1700000000 | F23: =D23-E23 | G23: =F23/E23
A24: 5 | B24: Tổng tài sản | C24: VNĐ | D24: 39000000000 | E24: 33000000000 | F24: =D24-E24 | G24: =F24/E24
A25: 6 | B25: Vốn chủ sở hữu | C25: VNĐ | D25: 15000000000 | E25: 12900000000 | F25: =D25-E25 | G25: =F25/E25
A26: 7 | B26: Hàng tồn kho cuối kỳ | C26: VNĐ | D26: 14650000000 | E26: 12800000000 | F26: =D26-E26 | G26: =F26/E26
A27: 8 | B27: Biên lợi nhuận gộp (Gross Margin) | C27: % | D27: 0.2 | E27: 0.196 | F27: =D27-E27 | G27: =F27/E27
A28: 9 | B28: Tỷ suất LNST / Doanh thu thuần (ROS) | C28: % | D28: 0.0347 | E28: 0.0234 | F28: =D28-E28 | G28: =F28/E28
A29: 10 | B29: Tỷ suất Sinh lời trên Vốn CSH (ROE) | C29: % | D29: 0.2151 | E29: 0.1411 | F29: =D29-E29 | G29: =F29/E29
A30: 11 | B30: Vòng quay hàng tồn kho (Vòng/năm) | C30: Vòng | D30: 5.04 | E30: 4.7 | F30: =D30-E30 | G30: =F30/E30
A31: 12 | B31: Hệ số Nợ phải trả / Tổng tài sản | C31: % | D31: 0.6154 | E31: 0.6091 | F31: =D31-E31 | G31: =F31/E31

Sheet 2. Bang Can Doi Ke Toan
A1: CÔNG TY CỔ PHẦN BÁCH HÓA VIỆT | E1: Mẫu số B 01 - DN
A2: Địa chỉ: Số 128 Đường Nguyễn Thị Minh Khai, Quận 3, TP. Hồ Chí Minh | E2: (Ban hành theo Thông tư số 200/2014/TT-BTC
A3: Mã số thuế: 0312345678 | ĐT: (028) 3930 8888 | E3: Ngày 22/12/2014 của Bộ Tài chính)
A5: BẢNG CÂN ĐỐI KẾ TOÁN
A6: Tại ngày 31 tháng 12 năm 2026
E7: Đơn vị tính: Việt Nam đồng (VNĐ)
A8: Mã số | B8: CHỈ TIÊU | C8: Thuyết minh | D8: Số cuối năm (31/12/2026) | E8: Số đầu năm (01/01/2026)
A9: 100 | B9: A. TÀI SẢN NGẮN HẠN | D9: =D10+D13+D14+D18+D19 | E9: =E10+E13+E14+E18+E19
A10: 110 | B10: I. Tiền và các khoản tương đương tiền | C10: V.01 | D10: =D11+D12 | E10: =E11+E12
A11: 111 | B11: 1. Tiền mặt tại chuỗi siêu thị và két quỹ | D11: 850000000 | E11: 600000000
A12: 112 | B12: 2. Tiền gửi ngân hàng không kỳ hạn | D12: 4000000000 | E12: 2600000000
A13: 120 | B13: II. Đầu tư tài chính ngắn hạn (Tiền gửi 3 tháng) | C13: V.02 | D13: 2000000000 | E13: 1500000000
A14: 130 | B14: III. Các khoản phải thu ngắn hạn | C14: V.03 | D14: =SUM(D15:D17) | E14: =SUM(E15:E17)
A15: 131 | B15: 1. Phải thu ngắn hạn của khách hàng (Đại lý, B2B) | C15: V.03a | D15: 3250000000 | E15: 2800000000
A16: 132 | B16: 2. Trả trước cho người bán ngắn hạn | D16: 820000000 | E16: 650000000
A17: 137 | B17: 3. Dự phòng phải thu ngắn hạn khó đòi (*) | C17: V.03b | D17: -70000000 | E17: -50000000
A18: 140 | B18: IV. Hàng tồn kho (Hàng hóa tại 28 siêu thị & tổng kho) | C18: V.04 | D18: 14650000000 | E18: 12800000000
A19: 150 | B19: V. Tài sản ngắn hạn khác (Thuế GTGT khấu trừ) | C19: V.05 | D19: 300000000 | E19: 200000000
A20: 200 | B20: B. TÀI SẢN DÀI HẠN | D20: =D21+D28+D29 | E20: =E21+E28+E29
A21: 220 | B21: I. Tài sản cố định | C21: V.06 | D21: =D22+D25 | E21: =E22+E25
A22: 221 | B22: 1. Tài sản cố định hữu hình (Quầy kệ, xe tải, kho lạnh) | D22: =D23+D24 | E22: =E23+E24
A23: 222 | B23: - Nguyên giá | D23: 12500000000 | E23: 10200000000
A24: 223 | B24: - Giá trị hao mòn lũy kế (*) | D24: -4200000000 | E24: -3100000000
A25: 227 | B25: 2. Tài sản cố định vô hình (Phần mềm ERP bán lẻ & Brand) | D25: =D26+D27 | E25: =E26+E27
A26: 228 | B26: - Nguyên giá | D26: 2400000000 | E26: 2000000000
A27: 229 | B27: - Giá trị hao mòn lũy kế (*) | D27: -800000000 | E27: -500000000
A28: 240 | B28: II. Tài sản dở dang dài hạn (Nâng cấp kho lạnh) | C28: V.07 | D28: 1100000000 | E28: 1500000000
A29: 260 | B29: III. Tài sản dài hạn khác (Đặt cọc thuê 28 mặt bằng) | C29: V.08 | D29: 2200000000 | E29: 1800000000
A30: 270 | B30: TỔNG CỘNG TÀI SẢN (270 = 100 + 200) | D30: =D9+D20 | E30: =E9+E20
A31: 300 | B31: C. NỢ PHẢI TRẢ | D31: =D32+D38 | E31: =E32+E38
A32: 310 | B32: I. Nợ ngắn hạn | C32: V.09 | D32: =SUM(D33:D37) | E32: =SUM(E33:E37)
A33: 311 | B33: 1. Phải trả người bán ngắn hạn (Nhà cung cấp FMCG) | D33: 9850000000 | E33: 8200000000
A34: 312 | B34: 2. Người mua trả tiền trước ngắn hạn (Voucher, thẻ quà) | D34: 450000000 | E34: 350000000
A35: 313 | B35: 3. Thuế và các khoản phải nộp Nhà nước | C35: V.10 | D35: 620000000 | E35: 480000000
A36: 314 | B36: 4. Phải trả người lao động (Lương 320 nhân viên chuỗi) | D36: 780000000 | E36: 620000000
A37: 320 | B37: 5. Vay và nợ thuê tài chính ngắn hạn (Tài trợ hàng Tết) | C37: V.11 | D37: 8500000000 | E37: 7200000000
A38: 330 | B38: II. Nợ dài hạn (Vay ngân hàng đầu tư xe tải & kho lạnh) | C38: V.12 | D38: 3800000000 | E38: 3250000000
A39: 400 | B39: D. VỐN CHỦ SỞ HỮU | D39: =D40 | E39: =E40
A40: 410 | B40: I. Vốn chủ sở hữu | C40: V.13 | D40: =D41+D42+D43 | E40: =E41+E42+E43
A41: 411 | B41: 1. Vốn góp của chủ sở hữu | D41: 10000000000 | E41: 10000000000
...

Sheet 3. KQKD
A1: CÔNG TY CỔ PHẦN BÁCH HÓA VIỆT | E1: Mẫu số B 02 - DN
A2: Địa chỉ: Số 128 Đường Nguyễn Thị Minh Khai, Quận 3, TP. Hồ Chí Minh | E2: (Ban hành theo Thông tư số 200/2014/TT-BTC
A3: Mã số thuế: 0312345678 | ĐT: (028) 3930 8888 | E3: Ngày 22/12/2014 của Bộ Tài chính)
A5: BÁO CÁO KẾT QUẢ HOẠT ĐỘNG KINH DOANH
A6: Năm 2026
E7: Đơn vị tính: Việt Nam đồng (VNĐ)
A8: Mã số | B8: CHỈ TIÊU | C8: Thuyết minh | D8: Năm 2026 (Kỳ này) | E8: Năm 2025 (Kỳ trước)
A9: 01 | B9: 1. Doanh thu bán hàng và cung cấp dịch vụ | C9: VI.01 | D9: 86500000000 | E9: 72800000000
A10: 02 | B10: 2. Các khoản giảm trừ doanh thu (Hàng trả lại, giảm giá) | C10: VI.02 | D10: 0 | E10: 0
A11: 10 | B11: 3. Doanh thu thuần về bán hàng và CCDV (10 = 01 - 02) | C11: VI.03 | D11: =D9-D10 | E11: =E9-E10
A12: 11 | B12: 4. Giá vốn hàng bán (FMCG và đồ uống) | C12: VI.04 | D12: 69200000000 | E12: 58531200000
A13: 20 | B13: 5. Lợi nhuận gộp về bán hàng và CCDV (20 = 10 - 11) | D13: =D11-D12 | E13: =E11-E12
A14: 21 | B14: 6. Doanh thu hoạt động tài chính (Chiết khấu TT) | C14: VI.05 | D14: 420000000 | E14: 310000000
A15: 22 | B15: 7. Chi phí tài chính (Lãi vay ngắn hạn tài trợ tồn kho) | C15: VI.06 | D15: 860000000 | E15: 715000000
A16: 23 | B16: - Trong đó: Chi phí lãi vay | D16: 820000000 | E16: 680000000
A17: 25 | B17: 8. Chi phí bán hàng (Thuê 28 mặt bằng, nhân viên POS) | C17: VI.07 | D17: 10850000000 | E17: 9320000000
A18: 26 | B18: 9. Chi phí quản lý doanh nghiệp (ERP, văn phòng) | C18: VI.08 | D18: 2360000000 | E18: 2038800000
A19: 30 | B19: 10. Lợi nhuận thuần từ HĐKD (30 = 20 + 21 - 22 - 25 - 26) | D19: =D13+D14-D15-D17-D18 | E19: =E13+E14-E15-E17-E18
A20: 31 | B20: 11. Thu nhập khác (Thanh lý phế liệu, quầy kệ) | C20: VI.09 | D20: 120000000 | E20: 80000000
A21: 32 | B21: 12. Chi phí khác | C21: VI.10 | D21: 20000000 | E21: 20000000
A22: 40 | B22: 13. Lợi nhuận khác (40 = 31 - 32) | D22: =D20-D21 | E22: =E20-E21
A23: 50 | B23: 14. TỔNG LỢI NHUẬN KẾ TOÁN TRƯỚC THUẾ (50 = 30 + 40) | D23: =D19+D22 | E23: =E19+E22
A24: 51 | B24: 15. Chi phí thuế TNDN hiện hành (20%) | C24: VI.11 | D24: 750000000 | E24: 425000000
A25: 52 | B25: 16. Chi phí thuế TNDN hoãn lại | D25: 0 | E25: 0
A26: 60 | B26: 17. LỢI NHUẬN SAU THUẾ TNDN (60 = 50 - 51 - 52) | D26: =D23-D24-D25 | E26: =E23-E24-E25
A27: 70 | B27: 18. Lãi cơ bản trên cổ phiếu (EPS) (VNĐ/CP) | C27: VI.12 | D27: =ROUND(D26/1000000, 0) | E27: =ROUND(E26/1000000, 0)
B31: Người lập biểu (Ký, họ tên) | C31: Kế toán trưởng (Ký, họ tên) | E31: TP.HCM, ngày 20 tháng 01 năm 2027 Tổng Giám đốc (Ký, đóng dấu)
B35: Lê Thị Cẩm Tú | C35: Phạm Minh Đức | E35: Nguyễn Hoàng Mai

Sheet 4. Luu Chuyen Tien Te
A1: CÔNG TY CỔ PHẦN BÁCH HÓA VIỆT | E1: Mẫu số B 03 - DN
A2: Địa chỉ: Số 128 Đường Nguyễn Thị Minh Khai, Quận 3, TP. Hồ Chí Minh | E2: (Ban hành theo Thông tư số 200/2014/TT-BTC
A3: Mã số thuế: 0312345678 | ĐT: (028) 3930 8888 | E3: Ngày 22/12/2014 của Bộ Tài chính)
A5: BÁO CÁO LƯU CHUYỂN TIỀN TỆ (PHƯƠNG PHÁP GIÁN TIẾP)
A6: Năm 2026
E7: Đơn vị tính: Việt Nam đồng (VNĐ)
A8: Mã số | B8: CHỈ TIÊU | C8: Thuyết minh | D8: Năm 2026 (Kỳ này) | E8: Năm 2025 (Kỳ trước)
A9: I | B9: LƯU CHUYỂN TIỀN TỪ HOẠT ĐỘNG KINH DOANH
A10: 01 | B10: 1. Lợi nhuận trước thuế | D10: ='3. KQKD'!D23 | E10: ='3. KQKD'!E23
A11: 02 | B11: 2. Điều chỉnh cho các khoản:
A12: 03 | B12: - Khấu hao TSCĐ và BĐSĐT | D12: 1400000000 | E12: 1150000000
A13: 04 | B13: - Các khoản dự phòng | D13: 20000000 | E13: 15000000
A14: 06 | B14: - Chi phí lãi vay | D14: 820000000 | E14: 680000000
A15: 08 | B15: 3. Lợi nhuận từ HĐKD trước thay đổi vốn lưu động | D15: =SUM(D10:D14) | E15: =SUM(E10:E14)
A16: 09 | B16: - Tăng/giảm các khoản phải thu | D16: -600000000 | E16: -450000000
A17: 10 | B17: - Tăng/giảm hàng tồn kho | D17: -1850000000 | E17: -1600000000
A18: 11 | B18: - Tăng/giảm các khoản phải trả (chiếm dụng vốn NCC) | D18: 1950000000 | E18: 1420000000
A19: 14 | B19: - Tiền lãi vay đã trả | D19: -820000000 | E19: -680000000
A20: 15 | B20: - Thuế thu nhập doanh nghiệp đã nộp | D20: -670000000 | E20: -410000000
A21: 20 | B21: Lưu chuyển tiền thuần từ HĐKD (Mã 20) | D21: =SUM(D15:D20) | E21: =SUM(E15:E20)
A22: II | B22: LƯU CHUYỂN TIỀN TỪ HOẠT ĐỘNG ĐẦU TƯ
A23: 21 | B23: 1. Tiền chi mua sắm, nâng cấp quầy kệ, kho lạnh và xe tải | D23: -3020000000 | E23: -2450000000
A24: 23 | B24: 2. Tiền gửi tiết kiệm ngân hàng có kỳ hạn | D24: -500000000 | E24: -500000000
A25: 27 | B25: 3. Tiền thu lãi cho vay, chiết khấu thanh toán | D25: 420000000 | E25: 310000000
A26: 30 | B26: Lưu chuyển tiền thuần từ HĐĐT (Mã 30) | D26: =SUM(D23:D25) | E26: =SUM(E23:E25)
A27: III | B27: LƯU CHUYỂN TIỀN TỪ HOẠT ĐỘNG TÀI CHÍNH
A28: 33 | B28: 1. Tiền thu từ đi vay ngắn hạn ngân hàng | D28: 8500000000 | E28: 7200000000
A29: 34 | B29: 2. Tiền trả nợ gốc vay ngân hàng | D29: -7200000000 | E29: -6100000000
A30: 36 | B30: 3. Cổ tức, lợi nhuận đã trả cho chủ sở hữu | D30: -800000000 | E30: -600000000
A31: 40 | B31: Lưu chuyển tiền thuần từ HĐTC (Mã 40) | D31: =SUM(D28:D30) | E31: =SUM(E28:E30)
A32: 50 | B32: LƯU CHUYỂN TIỀN THUẦN TRONG NĂM (50 = 20 + 30 + 40) | D32: =D21+D26+D31 | E32: =E21+E26+E31
A33: 60 | B33: Tiền và tương đương tiền đầu năm | D33: 3200000000 | E33: 2690000000
A34: 61 | B34: Ảnh hưởng của thay đổi tỷ giá hối đoái | D34: 0 | E34: 0
A35: 70 | B35: TIỀN VÀ TƯƠNG ĐƯƠNG TIỀN CUỐI NĂM (70 = 50 + 60 + 61) | C35: V.01 | D35: =D32+D33+D34 | E35: =E32+E33+E34
B39: Người lập biểu (Ký, họ tên) | C39: Kế toán trưởng (Ký, họ tên) | E39: TP.HCM, ngày 20 tháng 01 năm 2027 Tổng Giám đốc (Ký, đóng dấu)
B43: Lê Thị Cẩm Tú | C43: Phạm Minh Đức | E43: Nguyễn Hoàng Mai

Sheet 5. Thuyet Minh BCTC
A1: CÔNG TY CỔ PHẦN BÁCH HÓA VIỆT | E1: Mẫu số B 09 - DN
A2: Địa chỉ: Số 128 Đường Nguyễn Thị Minh Khai, Quận 3, TP. Hồ Chí Minh | E2: (Ban hành theo Thông tư số 200/2014/TT-BTC
A3: Mã số thuế: 0312345678 | ĐT: (028) 3930 8888 | E3: Ngày 22/12/2014 của Bộ Tài chính)
A5: BẢN THUYẾT MINH BÁO CÁO TÀI CHÍNH CHỌN LỌC
A6: Năm 2026
E7: Đơn vị tính: Việt Nam đồng (VNĐ)
A9: 1. HÀNG TỒN KHO THEO NGÀNH HÀNG TẠI 28 SIÊU THỊ & TỔNG KHO (Thuyết minh V.04)
A10: STT | B10: Nhóm ngành hàng FMCG | C10: Giá trị 31/12/2026 | D10: Tỷ trọng (%) | E10: Giá trị 01/01/2026 | F10: Vòng quay (ngày)
A11: 1 | B11: Thực phẩm tươi sống & Chế biến sẵn (Fresh Food) | C11: 4250000000 | D11: =C11/$C$15 | E11: 3600000000 | F11: 12 ngày
A12: 2 | B12: Hàng bách hóa tiêu dùng & Đồ uống đóng gói (Grocery) | C12: 5820000000 | D12: =C12/$C$15 | E12: 5100000000 | F12: 38 ngày
A13: 3 | B13: Hóa mỹ phẩm & Chăm sóc cá nhân (Personal Care) | C13: 2650000000 | D13: =C13/$C$15 | E13: 2300000000 | F13: 55 ngày
A14: 4 | B14: Đồ gia dụng tiện ích & Thiết bị gia đình | C14: 1930000000 | D14: =C14/$C$15 | E14: 1800000000 | F14: 75 ngày
A15: TỔNG CỘNG HÀNG TỒN KHO | C15: =SUM(C11:C14) | D15: =SUM(D11:D14) | E15: =SUM(E11:E14) | F15: Bình quân 72 ngày
A17: 2. PHẢI TRẢ NGƯỜI BÁN NGẮN HẠN & KỲ HẠN CÔNG NỢ (Thuyết minh V.09)
A18: Mã NCC | B18: Nhà cung cấp thực phẩm / Hàng hóa | C18: Số dư nợ 31/12/2026 | D18: Kỳ hạn công nợ | E18: Chiết khấu thương mại | F18: Tình trạng thanh toán
A19: NCC01 | B19: Công ty CP Sữa Việt Nam (Vinamilk) | C19: 2850000000 | D19: 45 ngày | E19: 2,5% nếu trả trong 15 ngày | F19: Trong hạn chuẩn
A20: NCC02 | B20: Tập đoàn Masan Consumer (Gia vị & Mì ăn liền) | C20: 2340000000 | D20: 45 ngày | E20: 2,0% theo doanh số quý | F20: Trong hạn chuẩn
A21: NCC03 | B21: Công ty TNHH Unilever Việt Nam | C21: 1860000000 | D21: 60 ngày | E21: 3,0% chiết khấu kệ hàng | F21: Trong hạn chuẩn
A22: NCC04 | B22: Công ty CP Chăn nuôi C.P. Việt Nam (Thịt tươi) | C22: 1450000000 | D22: 30 ngày | E22: 1,5% chiết khấu sản lượng | F22: Trong hạn chuẩn
A23: NCC05 | B23: Các nhà cung cấp nông sản, hàng gia dụng khác (86 NCC) | C23: 1350000000 | D23: 30 - 45 ngày | E23: 1,0% - 2,0% | F23: Trong hạn chuẩn
A24: TỔNG CỘNG PHẢI TRẢ NGƯỜI BÁN | C24: =SUM(C19:C23) | D24: Bình quân 45 ngày
A26: 3. DOANH THU THUẦN THEO KÊNH BÁN LẺ & ONLINE (Thuyết minh VI.01)
A27: STT | B27: Kênh bán hàng & Dịch vụ | C27: Doanh thu năm 2026 | D27: Tỷ trọng (%) | E27: Doanh thu năm 2025 | F27: Tăng trưởng
A28: 1 | B28: Kênh Siêu thị trực tiếp (In-store 28 cửa hàng) | C28: 64875000000 | D28: =C28/$C$31 | E28: 56784000000 | F28: =(C28-E28)/E28
A29: 2 | B29: Kênh Giao hàng hỏa tốc App VietMart & Zalo Mini App | C29: 14705000000 | D29: =C29/$C$31 | E29: 10920000000 | F29: =(C29-E29)/E29
A30: 3 | B30: Kênh B2B Cung ứng suất ăn công nghiệp & Trường học | C30: 6920000000 | D30: =C30/$C$31 | E30: 5096000000 | F30: =(C30-E30)/E30
A31: TỔNG CỘNG DOANH THU THUẦN | C31: =SUM(C28:C30) | D31: =SUM(D28:D30) | E31: =SUM(E28:E30) | F31: =(C31-E31)/E31

Sheet 6. Phan Tich Tai Chinh
A1: CÔNG TY CỔ PHẦN BÁCH HÓA VIỆT | E1: Mẫu số QT - 02
A2: Địa chỉ: Số 128 Đường Nguyễn Thị Minh Khai, Quận 3, TP. Hồ Chí Minh | E2: (Ban hành theo Thông tư số 200/2014/TT-BTC
A3: Mã số thuế: 0312345678 | ĐT: (028) 3930 8888 | E3: Ngày 22/12/2014 của Bộ Tài chính)
A5: PHÂN TÍCH CHỈ SỐ TÀI CHÍNH & MÔ HÌNH DUPONT NGÀNH BÁN LẺ
A6: Giai đoạn 2025 - 2026
E7: Đơn vị tính: Tỷ lệ & Lần
A8: STT | B8: Nhóm chỉ tiêu / Chỉ số tài chính | C8: Công thức tính | D8: Năm 2026 | E8: Năm 2025 | F8: Chuẩn ngành Bán lẻ FMCG | G8: Đánh giá & Khuyến nghị
A9: I | B9: NHÓM CHỈ SỐ KHẢ NĂNG THANH TOÁN (LIQUIDITY)
A10: 1 | B10: Hệ số thanh toán hiện hành (Current Ratio) | C10: TS ngắn hạn / Nợ ngắn hạn | D10: ='2. Bang Can Doi Ke Toan'!D9/'2. Bang Can Doi Ke Toan'!D32 | E10: ='2. Bang Can Doi Ke Toan'!E9/'2. Bang Can Doi Ke Toan'!E32 | F10: 1.1 - 1.4 | G10: 1.28 lần; đạt chuẩn an toàn ngành bán lẻ
A11: 2 | B11: Hệ số thanh toán nhanh (Quick Ratio) | C11: (Tiền + ĐT ngắn hạn + Phải thu) / Nợ ngắn hạn | D11: =('2. Bang Can Doi Ke Toan'!D10+'2. Bang Can Doi Ke Toan'!D13+'2. Bang Can Doi Ke Toan'!D14)/'2. Bang Can Doi Ke Toan'!D32 | E11: =('2. Bang Can Doi Ke Toan'!E10+'2. Bang Can Doi Ke Toan'!E13+'2. Bang Can Doi Ke Toan'!E14)/'2. Bang Can Doi Ke Toan'!E32 | F11: 0.4 - 0.7 | G11: 0.54 lần; phù hợp do tồn kho chiếm 57% TSNH
A12: 3 | B12: Hệ số thanh toán tức thời (Cash Ratio) | C12: Tiền và tương đương tiền / Nợ ngắn hạn | D12: ='2. Bang Can Doi Ke Toan'!D10/'2. Bang Can Doi Ke Toan'!D32 | E12: ='2. Bang Can Doi Ke Toan'!E10/'2. Bang Can Doi Ke Toan'!E32 | F12: 0.15 - 0.30 | G12: 0.24 lần; dòng tiền mặt từ chuỗi bán lẻ ổn định
A13: II | B13: NHÓM CHỈ SỐ CƠ CẤU VỐN & ĐÒN BẨY (LEVERAGE)
A14: 4 | B14: Hệ số Nợ trên Tổng tài sản (Debt/Assets) | C14: Tổng nợ phải trả / Tổng tài sản | D14: ='2. Bang Can Doi Ke Toan'!D31/'2. Bang Can Doi Ke Toan'!D30 | E14: ='2. Bang Can Doi Ke Toan'!E31/'2. Bang Can Doi Ke Toan'!E30 | F14: 55% - 70% | G14: 61.5%; bình thường do chiếm dụng vốn nhà cung cấp
A15: 5 | B15: Hệ số Nợ trên Vốn chủ sở hữu (D/E) | C15: Tổng nợ phải trả / Vốn CSH | D15: ='2. Bang Can Doi Ke Toan'!D31/'2. Bang Can Doi Ke Toan'!D39 | E15: ='2. Bang Can Doi Ke Toan'!E31/'2. Bang Can Doi Ke Toan'!E39 | F15: 1.5 - 2.5 | G15: 1.60 lần; đòn bẩy hoạt động thương mại hiệu quả
A16: 6 | B16: Hệ số khả năng chi trả lãi vay (ICR) | C16: EBIT / Chi phí lãi vay | D16: =('3. KQKD'!D23+'3. KQKD'!D16)/'3. KQKD'!D16 | E16: =('3. KQKD'!E23+'3. KQKD'!E16)/'3. KQKD'!E16 | F16: > 3.0 lần | G16: 5.57 lần; lợi nhuận thừa khả năng trang trải lãi
A17: III | B17: NHÓM CHỈ SỐ HIỆU QUẢ HOẠT ĐỘNG (EFFICIENCY)
A18: 7 | B18: Vòng quay hàng tồn kho (Inventory Turnover) | C18: Giá vốn hàng bán / Tồn kho bình quân | D18: ='3. KQKD'!D12/(('2. Bang Can Doi Ke Toan'!D18+'2. Bang Can Doi Ke Toan'!E18)/2) | E18: ='3. KQKD'!E12/'2. Bang Can Doi Ke Toan'!E18 | F18: 4.5 - 6.0 | G18: 5.04 vòng/năm; tốc độ giải phóng hàng hóa tốt
A19: 8 | B19: Thời gian lưu kho bình quân (DSI) | C19: 365 / Vòng quay hàng tồn kho | D19: =365/D18 | E19: =365/E18 | F19: 60 - 80 ngày | G19: 72.4 ngày; cần đẩy nhanh nhóm đồ gia dụng
A20: 9 | B20: Vòng quay các khoản phải thu | C20: Doanh thu thuần / Phải thu bình quân | D20: ='3. KQKD'!D11/(('2. Bang Can Doi Ke Toan'!D14+'2. Bang Can Doi Ke Toan'!E14)/2) | E20: ='3. KQKD'!E11/'2. Bang Can Doi Ke Toan'!E14 | F20: > 20 vòng | G20: 23.38 vòng/năm; thu hồi tiền B2B trong 15 ngày
A21: 10 | B21: Vòng quay Tổng tài sản (Asset Turnover) | C21: Doanh thu thuần / Tổng TS bình quân | D21: ='3. KQKD'!D11/(('2. Bang Can Doi Ke Toan'!D30+'2. Bang Can Doi Ke Toan'!E30)/2) | E21: ='3. KQKD'!E11/'2. Bang Can Doi Ke Toan'!E30 | F21: 2.0 - 3.0 | G21: 2.40 vòng/năm; tài sản tạo doanh số vượt trội
A22: IV | B22: NHÓM CHỈ SỐ SINH LỜI & MÔ HÌNH DUPONT (PROFITABILITY)
A23: 11 | B23: Tỷ suất Lợi nhuận gộp (Gross Margin) | C23: Lợi nhuận gộp / Doanh thu thuần | D23: ='3. KQKD'!D13/'3. KQKD'!D11 | E23: ='3. KQKD'!E13/'3. KQKD'!E11 | F23: 18% - 22% | G23: 20.0%; ổn định vững chắc cho ngành FMCG
A24: 12 | B24: Tỷ suất Sinh lời trên Doanh thu (ROS) | C24: Lợi nhuận sau thuế / Doanh thu thuần | D24: ='3. KQKD'!D26/'3. KQKD'!D11 | E24: ='3. KQKD'!E26/'3. KQKD'!E11 | F24: 2.5% - 4.5% | G24: 3.47%; biên ròng mỏng đặc trưng của bán lẻ
A25: 13 | B25: Tỷ suất Sinh lời trên Tài sản (ROA) | C25: LNST / Tổng tài sản bình quân | D25: ='3. KQKD'!D26/(('2. Bang Can Doi Ke Toan'!D30+'2. Bang Can Doi Ke Toan'!E30)/2) | E25: ='3. KQKD'!E26/'2. Bang Can Doi Ke Toan'!E30 | F25: 6% - 10% | G25: 8.33%; hiệu quả sinh lời trên tài sản tốt
A26: 14 | B26: Tỷ suất Sinh lời trên Vốn CSH (ROE) | C26: LNST / Vốn CSH bình quân (DuPont) | D26: ='3. KQKD'!D26/(('2. Bang Can Doi Ke Toan'!D39+'2. Bang Can Doi Ke Toan'!E39)/2) | E26: ='3. KQKD'!E26/'2. Bang Can Doi Ke Toan'!E39 | F26: 18% - 25% | G26: 21.51%; ROE rất cao nhờ vòng quay tài sản cao
A28: V. KẾT LUẬN & ĐẶC TRƯNG TÀI CHÍNH BÁN LẺ DÀNH CHO BÀI TẬP PHÂN TÍCH
A29: 1. Đặc trưng biên lợi nhuận mỏng nhưng ROE khủng: ROS chỉ đạt 3,47% nhưng ROE lên tới 21,51% nhờ Vòng quay Tổng tài sản đạt 2,40 vòng/năm.
A30: 2. Mô hình chiếm dụng vốn nhà cung cấp: Nợ người bán lên tới 9.850 tỷ đồng (kỳ hạn trả 45 ngày), trong khi bán lẻ thu tiền mặt ngay lập tức giúp bù đắp thanh toán nhanh.
A31: 3. Điểm khuyến nghị trọng tâm cho học viên phân tích: Cần áp dụng Mô hình DuPont (ROE = ROS x Vòng quay TS x Đòn bẩy tài chính) để giải thích sự thành công của chuỗi siêu thị!
